{"delayTime":18267,"error":"{\n    \"error_type\": \"<class 'ConnectionRefusedError'>\",\n    \"error_message\": \"[Errno 111] Connection refused\",\n    \"error_traceback\": \"Traceback (most recent call last):\\n  File \\\"/usr/local/lib/python3.8/dist-packages/runpod/serverless/modules/job.py\\\", line 82, in run_job\\n    job_output = handler(job)\\n  File \\\"comfy_runpod.py\\\", line 69, in run_prompt\\n    ws.connect(\\\"ws://{}/ws?clientId={}\\\".format(server_address, client_id))\\n  File \\\"/usr/local/lib/python3.8/dist-packages/websocket/_core.py\\\", line 249, in connect\\n    self.sock, addrs = connect(url, self.sock_opt, proxy_info(**options),\\n  File \\\"/usr/local/lib/python3.8/dist-packages/websocket/_http.py\\\", line 130, in connect\\n    sock = _open_socket(addrinfo_list, options.sockopt, options.timeout)\\n  File \\\"/usr/local/lib/python3.8/dist-packages/websocket/_http.py\\\", line 205, in _open_socket\\n    raise err\\n  File \\\"/usr/local/lib/python3.8/dist-packages/websocket/_http.py\\\", line 185, in _open_socket\\n    sock.connect(address)\\nConnectionRefusedError: [Errno 111] Connection refused\\n\",\n    \"host_name\": \"i23pqmpyc929gv-64410b8b\",\n    \"pod_id\": \"i23pqmpyc929gv\"\n}","executionTime":800,"id":"sync-bf064733-5017-441f-819b-94110a097541","status":"FAILED"}